Building DAG of jobs...
Using shell: /bin/bash
Provided cores: 8
Rules claiming more threads will be scaled down.
Job counts:
	count	jobs
	1	all
	1	generate_feature_matrix
	2

[Mon Mar 23 16:26:07 2020]
rule generate_feature_matrix:
    input: data/sample_input_SV.txt
    output: combined_matrix.txt
    jobid: 1

[Mon Mar 23 16:26:12 2020]
Error in rule generate_feature_matrix:
    jobid: 1
    output: combined_matrix.txt

RuleException:
URLError in line 14 of /Users/jagathvytheeswaran/SVFX/Snakefile:
<urlopen error [Errno 2] No such file or directory: '/Users/jagathvytheeswaran/SVFX/gfm_script.py'>
  File "/Users/jagathvytheeswaran/SVFX/Snakefile", line 14, in __rule_generate_feature_matrix
  File "/usr/local/Cellar/python/3.6.5_1/Frameworks/Python.framework/Versions/3.6/lib/python3.6/urllib/request.py", line 223, in urlopen
  File "/usr/local/Cellar/python/3.6.5_1/Frameworks/Python.framework/Versions/3.6/lib/python3.6/urllib/request.py", line 526, in open
  File "/usr/local/Cellar/python/3.6.5_1/Frameworks/Python.framework/Versions/3.6/lib/python3.6/urllib/request.py", line 544, in _open
  File "/usr/local/Cellar/python/3.6.5_1/Frameworks/Python.framework/Versions/3.6/lib/python3.6/urllib/request.py", line 504, in _call_chain
  File "/usr/local/Cellar/python/3.6.5_1/Frameworks/Python.framework/Versions/3.6/lib/python3.6/urllib/request.py", line 1452, in file_open
  File "/usr/local/Cellar/python/3.6.5_1/Frameworks/Python.framework/Versions/3.6/lib/python3.6/urllib/request.py", line 1491, in open_local_file
  File "/usr/local/Cellar/python/3.6.5_1/Frameworks/Python.framework/Versions/3.6/lib/python3.6/concurrent/futures/thread.py", line 56, in run
Shutting down, this might take some time.
Exiting because a job execution failed. Look above for error message
Complete log: /Users/jagathvytheeswaran/SVFX/.snakemake/log/2020-03-23T162607.690180.snakemake.log
